Workbook

Sheet 📋 Instruções
B2: 🏆 BOLÃO DA COPA DO MUNDO
B5: COMO FUNCIONA O BOLÃO
B7: 1. Aba 'Participantes' | C7: Cadastre os nomes dos participantes (máx. 20)
B8: 2. Aba 'Jogos' | C8: Lista completa de jogos com placares reais
B9: 3. Aba 'Palpites' | C9: Cada participante preenche seus palpites
B10: 4. Aba 'Pontuação' | C10: Pontos calculados automaticamente
B11: 5. Aba 'Ranking' | C11: Classificação geral com critérios de desempate
B13: SISTEMA DE PONTUAÇÃO
B15: ✅ Placar exato | C15: 3 pontos
B16: ✅ Vencedor correto + diferença de gols correta | C16: 2 pontos
B17: ✅ Somente vencedor/empate correto | C17: 1 ponto
B18: ❌ Errou | C18: 0 pontos
B20: CRITÉRIOS DE DESEMPATE
B22: 1º | C22: Maior nº de placares exatos
B23: 2º | C23: Maior nº de vencedores corretos
B24: 3º | C24: Maior pontuação em jogos eliminatórios
B25: 4º | C25: Ordem alfabética
B27: PREENCHIMENTO
B29: 🟢 Células VERDES | C29: Preencha os palpites aqui
B30: ⚪ Células CINZAS | C30: Calculadas automaticamente – não edite
B31: 🟡 Células AMARELAS | C31: Resultados reais – preencha após cada jogo

Sheet 👥 Participantes
B2: 👥 PARTICIPANTES DO BOLÃO
B5: # | C5: Nome do Participante | D5: Apelido (opcional)
B6: 1 | C6: Ana Silva
B7: 2 | C7: Bruno Costa
B8: 3 | C8: Carla Mendes
B9: 4 | C9: Diego Alves
B10: 5 | C10: Eduarda Lima
B11: 6
B12: 7
B13: 8
B14: 9
B15: 10
B16: 11
B17: 12
B18: 13
B19: 14
B20: 15
B21: 16
B22: 17
... B25: 20
C27: ↑ Preencha os nomes acima (máximo 20 participantes)

Sheet ⚽ Jogos
B2: ⚽ TABELA DE JOGOS – COPA DO MUNDO
B5: Jogo | C5: Fase | D5: Data | E5: Time 1 | F5: Gols 1 | G5: X | H5: Gols 2 | I5: Time 2 | J5: Grupo
B6: ━━━━━ GRUPO ━━━━━
B7: 1 | C7: Grupo | D7: 11/06/2026 | E7: México | F7: 2 | G7: X | H7: 0 | I7: África do Sul | J7: A
B8: 2 | C8: Grupo | D8: 11/06/2026 | E8: República da Coreia | G8: X | I8: República Tcheca | J8: A
B9: 3 | C9: Grupo | D9: 12/06/2026 | E9: Canadá | G9: X | I9: Bósnia e Herzegovina | J9: B
B10: 4 | C10: Grupo | D10: 12/06/2026 | E10: Estados Unidos | G10: X | I10: Paraguai | J10: D
B11: 5 | C11: Grupo | D11: 13/06/2026 | E11: Catar | G11: X | I11: Suíça | J11: B
B12: 6 | C12: Grupo | D12: 13/06/2026 | E12: Brasil | G12: X | I12: Marrocos | J12: C
B13: 7 | C13: Grupo | D13: 13/06/2026 | E13: Haiti | G13: X | I13: Escócia | J13: C
B14: 8 | C14: Grupo | D14: 13/06/2026 | E14: Austrália | G14: X | I14: Turquia | J14: D
B15: 9 | C15: Grupo | D15: 14/06/2026 | E15: Alemanha | G15: X | I15: Curaçau | J15: E
B16: 10 | C16: Grupo | D16: 14/06/2026 | E16: Costa do Marfim | G16: X | I16: Equador | J16: E
B17: 11 | C17: Grupo | D17: 14/06/2026 | E17: Holanda | G17: X | I17: Japão | J17: F
B18: 12 | C18: Grupo | D18: 14/06/2026 | E18: Suécia | G18: X | I18: Tunísia | J18: F
B19: 13 | C19: Grupo | D19: 15/06/2026 | E19: Espanha | G19: X | I19: Cabo Verde | J19: H
... B78: 72 | C78: Grupo | D78: 27/06/2026 | E78: Jordânia | G78: X | I78: Argentina | J78: J
B79: ━━━━━ 32-AVOS ━━━━━
B80: 73 | C80: 32-avos | D80: 28/06/2026 | E80: Segundo colocado do Grupo A | G80: X | I80: Segundo colocado do Grupo B
B81: 74 | C81: 32-avos | D81: 29/06/2026 | E81: Vencedor do Grupo E | G81: X | I81: Terceiro colocado dos Grupos A/B/C/D/F
B82: 75 | C82: 32-avos | D82: 29/06/2026 | E82: Vencedor do Grupo F | G82: X | I82: Segundo colocado do Grupo C
B83: 76 | C83: 32-avos | D83: 29/06/2026 | E83: Vencedor do Grupo C | G83: X | I83: Segundo colocado do Grupo F
B84: 77 | C84: 32-avos | D84: 30/06/2026 | E84: Vencedor do Grupo I | G84: X | I84: Terceiro colocado dos Grupos C/D/F/G/H
B85: 78 | C85: 32-avos | D85: 30/06/2026 | E85: Segundo colocado do Grupo E | G85: X | I85: Segundo colocado do Grupo I
B86: 79 | C86: 32-avos | D86: 30/06/2026 | E86: Vencedor do Grupo A | G86: X | I86: Terceiro colocado dos Grupos C/E/F/H/I
B87: 80 | C87: 32-avos | D87: 01/07/2026 | E87: Vencedor do Grupo L | G87: X | I87: Terceiro colocado dos Grupos E/H/I/J/K
B88: 81 | C88: 32-avos | D88: 01/07/2026 | E88: Vencedor do Grupo D | G88: X | I88: Terceiro colocado dos Grupos B/E/F/I/J
B89: 82 | C89: 32-avos | D89: 01/07/2026 | E89: Vencedor do Grupo G | G89: X | I89: Terceiro colocado dos Grupos A/E/H/I/J
B90: 83 | C90: 32-avos | D90: 02/07/2026 | E90: Segundo colocado do Grupo K | G90: X | I90: Segundo colocado do Grupo L
B91: 84 | C91: 32-avos | D91: 02/07/2026 | E91: Vencedor do Grupo H | G91: X | I91: Segundo colocado do Grupo J
... B95: 88 | C95: 32-avos | D95: 03/07/2026 | E95: Segundo colocado do Grupo D | G95: X | I95: Segundo colocado do Grupo G
B96: ━━━━━ OITAVAS ━━━━━
B97: 89 | C97: Oitavas | D97: 04/07/2026 | E97: Vencedor do jogo 74 | G97: X | I97: Vencedor do jogo 77
B98: 90 | C98: Oitavas | D98: 04/07/2026 | E98: Vencedor do jogo 73 | G98: X | I98: Vencedor do jogo 75
B99: 91 | C99: Oitavas | D99: 05/07/2026 | E99: Vencedor do jogo 76 | G99: X | I99: Vencedor do jogo 78
B100: 92 | C100: Oitavas | D100: 05/07/2026 | E100: Vencedor do jogo 79 | G100: X | I100: Vencedor do jogo 80
B101: 93 | C101: Oitavas | D101: 06/07/2026 | E101: Vencedor do jogo 83 | G101: X | I101: Vencedor do jogo 84
B102: 94 | C102: Oitavas | D102: 06/07/2026 | E102: Vencedor do jogo 81 | G102: X | I102: Vencedor do jogo 82
B103: 95 | C103: Oitavas | D103: 07/07/2026 | E103: Vencedor do jogo 86 | G103: X | I103: Vencedor do jogo 88
B104: 96 | C104: Oitavas | D104: 07/07/2026 | E104: Vencedor do jogo 85 | G104: X | I104: Vencedor do jogo 87
...

Sheet 🎯 Palpites
B2: 🎯 PALPITES – PARTICIPANTES 1 a 10
B5: # | C5: Time 1 | D5: X | E5: Time 2 | F5: ='👥 Participantes'!C6 -> Ana Silva | H5: ='👥 Participantes'!C7 -> Bruno Costa | J5: ='👥 Participantes'!C8 -> Carla Mendes | L5: ='👥 Participantes'!C9 -> Diego Alves | N5: ='👥 Participantes'!C10 -> Eduarda Lima | P5: ='👥 Participantes'!C11 | R5: ='👥 Participantes'!C12 | T5: ='👥 Participantes'!C13 | V5: ='👥 Participantes'!C14 | X5: ='👥 Participantes'!C15
F6: T1 | G6: T2 | H6: T1 | I6: T2 | J6: T1 | K6: T2 | L6: T1 | M6: T2 | N6: T1 | O6: T2 | P6: T1 | Q6: T2 | R6: T1 | S6: T2 | T6: T1 | U6: T2 | V6: T1 | W6: T2 | X6: T1 | Y6: T2
B7: ━━━ GRUPO ━━━
B8: 1 | C8: México | D8: X | E8: África do Sul | F8: 1 | G8: 0 | H8: 2 | I8: 0 | J8: 3 | K8: 1 | L8: 1 | M8: 1 | N8: 0 | O8: 1
B9: 2 | C9: República da Coreia | D9: X | E9: República Tcheca
B10: 3 | C10: Canadá | D10: X | E10: Bósnia e Herzegovina
B11: 4 | C11: Estados Unidos | D11: X | E11: Paraguai
B12: 5 | C12: Catar | D12: X | E12: Suíça
B13: 6 | C13: Brasil | D13: X | E13: Marrocos
B14: 7 | C14: Haiti | D14: X | E14: Escócia
B15: 8 | C15: Austrália | D15: X | E15: Turquia
B16: 9 | C16: Alemanha | D16: X | E16: Curaçau
B17: 10 | C17: Costa do Marfim | D17: X | E17: Equador
B18: 11 | C18: Holanda | D18: X | E18: Japão
B19: 12 | C19: Suécia | D19: X | E19: Tunísia
B20: 13 | C20: Espanha | D20: X | E20: Cabo Verde
... B79: 72 | C79: Jordânia | D79: X | E79: Argentina
B80: ━━━ 32-AVOS ━━━
B81: 73 | C81: Segundo colocado do Grupo A | D81: X | E81: Segundo colocado do Grupo B
B82: 74 | C82: Vencedor do Grupo E | D82: X | E82: Terceiro colocado dos Grupos A/B/C/D/F
B83: 75 | C83: Vencedor do Grupo F | D83: X | E83: Segundo colocado do Grupo C
B84: 76 | C84: Vencedor do Grupo C | D84: X | E84: Segundo colocado do Grupo F
B85: 77 | C85: Vencedor do Grupo I | D85: X | E85: Terceiro colocado dos Grupos C/D/F/G/H
B86: 78 | C86: Segundo colocado do Grupo E | D86: X | E86: Segundo colocado do Grupo I
B87: 79 | C87: Vencedor do Grupo A | D87: X | E87: Terceiro colocado dos Grupos C/E/F/H/I
B88: 80 | C88: Vencedor do Grupo L | D88: X | E88: Terceiro colocado dos Grupos E/H/I/J/K
B89: 81 | C89: Vencedor do Grupo D | D89: X | E89: Terceiro colocado dos Grupos B/E/F/I/J
B90: 82 | C90: Vencedor do Grupo G | D90: X | E90: Terceiro colocado dos Grupos A/E/H/I/J
B91: 83 | C91: Segundo colocado do Grupo K | D91: X | E91: Segundo colocado do Grupo L
B92: 84 | C92: Vencedor do Grupo H | D92: X | E92: Segundo colocado do Grupo J
... B96: 88 | C96: Segundo colocado do Grupo D | D96: X | E96: Segundo colocado do Grupo G
B97: ━━━ OITAVAS ━━━
B98: 89 | C98: Vencedor do jogo 74 | D98: X | E98: Vencedor do jogo 77
B99: 90 | C99: Vencedor do jogo 73 | D99: X | E99: Vencedor do jogo 75
B100: 91 | C100: Vencedor do jogo 76 | D100: X | E100: Vencedor do jogo 78
B101: 92 | C101: Vencedor do jogo 79 | D101: X | E101: Vencedor do jogo 80
B102: 93 | C102: Vencedor do jogo 83 | D102: X | E102: Vencedor do jogo 84
B103: 94 | C103: Vencedor do jogo 81 | D103: X | E103: Vencedor do jogo 82
B104: 95 | C104: Vencedor do jogo 86 | D104: X | E104: Vencedor do jogo 88
...

Sheet 🎯 Palpites (11-20)
B2: 🎯 PALPITES – PARTICIPANTES 11 a 20
B5: # | C5: Time 1 | D5: X | E5: Time 2 | F5: ='👥 Participantes'!C16 | H5: ='👥 Participantes'!C17 | J5: ='👥 Participantes'!C18 | L5: ='👥 Participantes'!C19 | N5: ='👥 Participantes'!C20 | P5: ='👥 Participantes'!C21 | R5: ='👥 Participantes'!C22 | T5: ='👥 Participantes'!C23 | V5: ='👥 Participantes'!C24 | X5: ='👥 Participantes'!C25
F6: T1 | G6: T2 | H6: T1 | I6: T2 | J6: T1 | K6: T2 | L6: T1 | M6: T2 | N6: T1 | O6: T2 | P6: T1 | Q6: T2 | R6: T1 | S6: T2 | T6: T1 | U6: T2 | V6: T1 | W6: T2 | X6: T1 | Y6: T2
B7: ━━━ GRUPO ━━━
B8: 1 | C8: México | D8: X | E8: África do Sul
B9: 2 | C9: República da Coreia | D9: X | E9: República Tcheca
B10: 3 | C10: Canadá | D10: X | E10: Bósnia e Herzegovina
B11: 4 | C11: Estados Unidos | D11: X | E11: Paraguai
B12: 5 | C12: Catar | D12: X | E12: Suíça
B13: 6 | C13: Brasil | D13: X | E13: Marrocos
B14: 7 | C14: Haiti | D14: X | E14: Escócia
B15: 8 | C15: Austrália | D15: X | E15: Turquia
B16: 9 | C16: Alemanha | D16: X | E16: Curaçau
B17: 10 | C17: Costa do Marfim | D17: X | E17: Equador
B18: 11 | C18: Holanda | D18: X | E18: Japão
B19: 12 | C19: Suécia | D19: X | E19: Tunísia
... B79: 72 | C79: Jordânia | D79: X | E79: Argentina
B80: ━━━ 32-AVOS ━━━
B81: 73 | C81: Segundo colocado do Grupo A | D81: X | E81: Segundo colocado do Grupo B
B82: 74 | C82: Vencedor do Grupo E | D82: X | E82: Terceiro colocado dos Grupos A/B/C/D/F
B83: 75 | C83: Vencedor do Grupo F | D83: X | E83: Segundo colocado do Grupo C
B84: 76 | C84: Vencedor do Grupo C | D84: X | E84: Segundo colocado do Grupo F
B85: 77 | C85: Vencedor do Grupo I | D85: X | E85: Terceiro colocado dos Grupos C/D/F/G/H
B86: 78 | C86: Segundo colocado do Grupo E | D86: X | E86: Segundo colocado do Grupo I
B87: 79 | C87: Vencedor do Grupo A | D87: X | E87: Terceiro colocado dos Grupos C/E/F/H/I
B88: 80 | C88: Vencedor do Grupo L | D88: X | E88: Terceiro colocado dos Grupos E/H/I/J/K
B89: 81 | C89: Vencedor do Grupo D | D89: X | E89: Terceiro colocado dos Grupos B/E/F/I/J
B90: 82 | C90: Vencedor do Grupo G | D90: X | E90: Terceiro colocado dos Grupos A/E/H/I/J
B91: 83 | C91: Segundo colocado do Grupo K | D91: X | E91: Segundo colocado do Grupo L
B92: 84 | C92: Vencedor do Grupo H | D92: X | E92: Segundo colocado do Grupo J
... B96: 88 | C96: Segundo colocado do Grupo D | D96: X | E96: Segundo colocado do Grupo G
B97: ━━━ OITAVAS ━━━
B98: 89 | C98: Vencedor do jogo 74 | D98: X | E98: Vencedor do jogo 77
B99: 90 | C99: Vencedor do jogo 73 | D99: X | E99: Vencedor do jogo 75
B100: 91 | C100: Vencedor do jogo 76 | D100: X | E100: Vencedor do jogo 78
B101: 92 | C101: Vencedor do jogo 79 | D101: X | E101: Vencedor do jogo 80
B102: 93 | C102: Vencedor do jogo 83 | D102: X | E102: Vencedor do jogo 84
B103: 94 | C103: Vencedor do jogo 81 | D103: X | E103: Vencedor do jogo 82
B104: 95 | C104: Vencedor do jogo 86 | D104: X | E104: Vencedor do jogo 88
B105: 96 | C105: Vencedor do jogo 85 | D105: X | E105: Vencedor do jogo 87
...

Sheet 📊 Pontuação
B2: 📊 PONTUAÇÃO POR JOGO
B5: # | C5: Time 1 | D5: Time 2 | E5: ='👥 Participantes'!C6 -> Ana Silva | F5: ='👥 Participantes'!C7 -> Bruno Costa | G5: ='👥 Participantes'!C8 -> Carla Mendes | H5: ='👥 Participantes'!C9 -> Diego Alves | I5: ='👥 Participantes'!C10 -> Eduarda Lima | J5: ='👥 Participantes'!C11 | K5: ='👥 Participantes'!C12 | L5: ='👥 Participantes'!C13 | M5: ='👥 Participantes'!C14 | N5: ='👥 Participantes'!C15 | O5: ='👥 Participantes'!C16 | P5: ='👥 Participantes'!C17 | Q5: ='👥 Participantes'!C18 | R5: ='👥 Participantes'!C19 | S5: ='👥 Participantes'!C20 | T5: ='👥 Participantes'!C21 | U5: ='👥 Participantes'!C22 | V5: ='👥 Participantes'!C23 | W5: ='👥 Participantes'!C24 | X5: ='👥 Participantes'!C25
B7: ━━━ GRUPO ━━━
B8: 1 | C8: México | D8: África do Sul | E8: =IF(OR(NOT(ISNUMBER('⚽ Jogos'!F7)),NOT(ISNUMBER('⚽ Jogos'!H7)),NOT(ISNUMBER('🎯 Palpites'!F8)),NOT(ISNUMBER('🎯 Palpites'!G8))),"", IF(AND('🎯 Palpites'!F8='⚽ Jogos'!F7,'🎯 Palpites'!G8='⚽ Jogos'!H7),3, IF(AND(SIGN('🎯 Palpites'!F8-'🎯 Palpites'!G8)=SIGN('⚽ Jogos'!F7-'⚽ Jogos'!H7),('🎯 Palpites'!F8-'🎯 Palpites'!G8)=('⚽ Jogos'!F7-'⚽ Jogos'!H7)),2, IF(SIGN('🎯 Palpites'!F8-'🎯 Palpites'!G8)=SIGN('⚽ Jogos'!F7-'⚽ Jogos'!H7),1, 0)))) -> 1 | F8: =IF(OR(NOT(ISNUMBER('⚽ Jogos'!F7)),NOT(ISNUMBER('⚽ Jogos'!H7)),NOT(ISNUMBER('🎯 Palpites'!H8)),NOT(ISNUMBER('🎯 Palpites'!I8))),"", IF(AND('🎯 Palpites'!H8='⚽ Jogos'!F7,'🎯 Palpites'!I8='⚽ Jogos'!H7),3, IF(AND(SIGN('🎯 Palpites'!H8-'🎯 Palpites'!I8)=SIGN('⚽ Jogos'!F7-'⚽ Jogos'!H7),('🎯 Palpites'!H8-'🎯 Palpites'!I8)=('⚽ Jogos'!F7-'⚽ Jogos'!H7)),2, IF(SIGN('🎯 Palpites'!H8-'🎯 Palpites'!I8)=SIGN('⚽ Jogos'!F7-'⚽ Jogos'!H7),1, 0)))) -> 3 | G8: =IF(OR(NOT(ISNUMBER('⚽ Jogos'!F7)),NOT(ISNUMBER('⚽ Jogos'!H7)),NOT(ISNUMBER('🎯 Palpites'!J8)),NOT(ISNUMBER('🎯 Palpites'!K8))),"", IF(AND('🎯 Palpites'!J8='⚽ Jogos'!F7,'🎯 Palpites'!K8='⚽ Jogos'!H7),3, IF(AND(SIGN('🎯 Palpites'!J8-'🎯 Palpites'!K8)=SIGN('⚽ Jogos'!F7-'⚽ Jogos'!H7),('🎯 Palpites'!J8-'🎯 Palpites'!K8)=('⚽ Jogos'!F7-'⚽ Jogos'!H7)),2, IF(SIGN('🎯 Palpites'!J8-'🎯 Palpites'!K8)=SIGN('⚽ Jogos'!F7-'⚽ Jogos'!H7),1, 0)))) -> 2 | H8: =IF(OR(NOT(ISNUMBER('⚽ Jogos'!F7)),NOT(ISNUMBER('⚽ Jogos'!H7)),NOT(ISNUMBER('🎯 Palpites'!L8)),NOT(ISNUMBER('🎯 Palpites'!M8))),"", IF(AND('🎯 Palpites'!L8='⚽ Jogos'!F7,'🎯 Palpites'!M8='⚽ Jogos'!H7),3, IF(AND(SIGN('🎯 Palpites'!L8-'🎯 Palpites'!M8)=SIGN('⚽ Jogos'!F7-'⚽ Jogos'!H7),('🎯 Palpites'!L8-'🎯 Palpites'!M8)=('⚽ Jogos'!F7-'⚽ Jogos'!H7)),2, IF(SIGN('🎯 Palpites'!L8-'🎯 Palpites'!M8)=SIGN('⚽ Jogos'!F7-'⚽ Jogos'!H7),1, 0)))) -> 0 | I8: =IF(OR(NOT(ISNUMBER('⚽ Jogos'!F7)),NOT(ISNUMBER('⚽ Jogos'!H7)),NOT(ISNUMBER('🎯 Palpites'!N8)),NOT(ISNUMBER('🎯 Palpites'!O8))),"", IF(AND('🎯 Palpites'!N8='⚽ Jogos'!F7,'🎯 Palpites'!O8='⚽ Jogos'!H7),3, IF(AND(SIGN('🎯 Palpites'!N8-'🎯 Palpites'!O8)=SIGN('⚽ Jogos'!F7-'⚽ Jogos'!H7),('🎯 Palpites'!N8-'🎯 Palpites'!O8)=('⚽ Jogos'!F7-'⚽ Jogos'!H7)),2, IF(SIGN('🎯 Palpites'!N8-'🎯 Palpites'!O8)=SIGN('⚽ Jogos'!F7-'⚽ Jogos'!H7),1, 0)))) -> 0 | J8: =IF(OR(NOT(ISNUMBER('⚽ Jogos'!F7)),NOT(ISNUMBER('⚽ Jogos'!H7)),NOT(ISNUMBER('🎯 Palpites'!P8)),NOT(ISNUMBER('🎯 Palpites'!Q8))),"", IF(AND('🎯 Palpites'!P8='⚽ Jogos'!F7,'🎯 Palpites'!Q8='⚽ Jogos'!H7),3, IF(AND(SIGN('🎯 Palpites'!P8-'🎯 Palpites'!Q8)=SIGN('⚽ Jogos'!F7-'⚽ Jogos'!H7),('🎯 Palpites'!P8-'🎯 Palpites'!Q8)=('⚽ Jogos'!F7-'⚽ Jogos'!H7)),2, IF(SIGN('🎯 Palpites'!P8-'🎯 Palpites'!Q8)=SIGN('⚽ Jogos'!F7-'⚽ Jogos'!H7),1, 0)))) | K8: =IF(OR(NOT(ISNUMBER('⚽ Jogos'!F7)),NOT(ISNUMBER('⚽ Jogos'!H7)),NOT(ISNUMBER('🎯 Palpites'!R8)),NOT(ISNUMBER('🎯 Palpites'!S8))),"", IF(AND('🎯 Palpites'!R8='⚽ Jogos'!F7,'🎯 Palpites'!S8='⚽ Jogos'!H7),3, IF(AND(SIGN('🎯 Palpites'!R8-'🎯 Palpites'!S8)=SIGN('⚽ Jogos'!F7-'⚽ Jogos'!H7),('🎯 Palpites'!R8-'🎯 Palpites'!S8)=('⚽ Jogos'!F7-'⚽ Jogos'!H7)),2, IF(SIGN('🎯 Palpites'!R8-'🎯 Palpites'!S8)=SIGN('⚽ Jogos'!F7-'⚽ Jogos'!H7),1, 0)))) | L8: =IF(OR(NOT(ISNUMBER('⚽ Jogos'!F7)),NOT(ISNUMBER('⚽ Jogos'!H7)),NOT(ISNUMBER('🎯 Palpites'!T8)),NOT(ISNUMBER('🎯 Palpites'!U8))),"", IF(AND('🎯 Palpites'!T8='⚽ Jogos'!F7,'🎯 Palpites'!U8='⚽ Jogos'!H7),3, IF(AND(SIGN('🎯 Palpites'!T8-'🎯 Palpites'!U8)=SIGN('⚽ Jogos'!F7-'⚽ Jogos'!H7),('🎯 Palpites'!T8-'🎯 Palpites'!U8)=('⚽ Jogos'!F7-'⚽ Jogos'!H7)),2, IF(SIGN('🎯 Palpites'!T8-'🎯 Palpites'!U8)=SIGN('⚽ Jogos'!F7-'⚽ Jogos'!H7),1, 0)))) | M8: =IF(OR(NOT(ISNUMBER('⚽ Jogos'!F7)),NOT(ISNUMBER('⚽ Jogos'!H7)),NOT(ISNUMBER('🎯 Palpites'!V8)),NOT(ISNUMBER('🎯 Palpites'!W8))),"", IF(AND('🎯 Palpites'!V8='⚽ Jogos'!F7,'🎯 Palpites'!W8='⚽ Jogos'!H7),3, IF(AND(SIGN('🎯 Palpites'!V8-'🎯 Palpites'!W8)=SIGN('⚽ Jogos'!F7-'⚽ Jogos'!H7),('🎯 Palpites'!V8-'🎯 Palpites'!W8)=('⚽ Jogos'!F7-'⚽ Jogos'!H7)),2, IF(SIGN('🎯 Palpites'!V8-'🎯 Palpites'!W8)=SIGN('⚽ Jogos'!F7-'⚽ Jogos'!H7),1, 0)))) | N8: =IF(OR(NOT(ISNUMBER('⚽ Jogos'!F7)),NOT(ISNUMBER('⚽ Jogos'!H7)),NOT(ISNUMBER('🎯 Palpites'!X8)),NOT(ISNUMBER('🎯 Palpites'!Y8))),"", IF(AND('🎯 Palpites'!X8='⚽ Jogos'!F7,'🎯 Palpites'!Y8='⚽ Jogos'!H7),3, IF(AND(SIGN('🎯 Palpites'!X8-'🎯 Palpites'!Y8)=SIGN('⚽ Jogos'!F7-'⚽ Jogos'!H7),('🎯 Palpites'!X8-'🎯 Palpites'!Y8)=('⚽ Jogos'!F7-'⚽ Jogos'!H7)),2, IF(SIGN('🎯 Palpites'!X8-'🎯 Palpites'!Y8)=SIGN('⚽ Jogos'!F7-'⚽ Jogos'!H7),1, 0)))) | O8: =IF(OR(NOT(ISNUMBER('⚽ Jogos'!F7)),NOT(ISNUMBER('⚽ Jogos'!H7)),NOT(ISNUMBER('🎯 Palpites (11-20)'!F8)),NOT(ISNUMBER('🎯 Palpites (11-20)'!G8))),"", IF(AND('🎯 Palpites (11-20)'!F8='⚽ Jogos'!F7,'🎯 Palpites (11-20)'!G8='⚽ Jogos'!H7),3, IF(AND(SIGN('🎯 Palpites (11-20)'!F8-'🎯 Palpites (11-20)'!G8)=SIGN('⚽ Jogos'!F7-'⚽ Jogos'!H7),('🎯 Palpites (11-20)'!F8-'🎯 Palpites (11-20)'!G8)=('⚽ Jogos'!F7-'⚽ Jogos'!H7)),2, IF(SIGN('🎯 Palpites (11-20)'!F8-'🎯 Palpites (11-20)'!G8)=SIGN('⚽ Jogos'!F7-'⚽ Jogos'!H7),1, 0)))) | P8: =IF(OR(NOT(ISNUMBER('⚽ Jogos'!F7)),NOT(ISNUMBER('⚽ Jogos'!H7)),NOT(ISNUMBER('🎯 Palpites (11-20)'!H8)),NOT(ISNUMBER('🎯 Palpites (11-20)'!I8))),"", IF(AND('🎯 Palpites (11-20)'!H8='⚽ Jogos'!F7,'🎯 Palpites (11-20)'!I8='⚽ Jogos'!H7),3, IF(AND(SIGN('🎯 Palpites (11-20)'!H8-'🎯 Palpites (11-20)'!I8)=SIGN('⚽ Jogos'!F7-'⚽ Jogos'!H7),('🎯 Palpites (11-20)'!H8-'🎯 Palpites (11-20)'!I8)=('⚽ Jogos'!F7-'⚽ Jogos'!H7)),2, IF(SIGN('🎯 Palpites (11-20)'!H8-'🎯 Palpites (11-20)'!I8)=SIGN('⚽ Jogos'!F7-'⚽ Jogos'!H7),1, 0)))) | Q8: =IF(OR(NOT(ISNUMBER('⚽ Jogos'!F7)),NOT(ISNUMBER('⚽ Jogos'!H7)),NOT(ISNUMBER('🎯 Palpites (11-20)'!J8)),NOT(ISNUMBER('🎯 Palpites (11-20)'!K8))),"", IF(AND('🎯 Palpites (11-20)'!J8='⚽ Jogos'!F7,'🎯 Palpites (11-20)'!K8='⚽ Jogos'!H7),3, IF(AND(SIGN('🎯 Palpites (11-20)'!J8-'🎯 Palpites (11-20)'!K8)=SIGN('⚽ Jogos'!F7-'⚽ Jogos'!H7),('🎯 Palpites (11-20)'!J8-'🎯 Palpites (11-20)'!K8)=('⚽ Jogos'!F7-'⚽ Jogos'!H7)),2, IF(SIGN('🎯 Palpites (11-20)'!J8-'🎯 Palpites (11-20)'!K8)=SIGN('⚽ Jogos'!F7-'⚽ Jogos'!H7),1, 0)))) | R8: =IF(OR(NOT(ISNUMBER('⚽ Jogos'!F7)),NOT(ISNUMBER('⚽ Jogos'!H7)),NOT(ISNUMBER('🎯 Palpites (11-20)'!L8)),NOT(ISNUMBER('🎯 Palpites (11-20)'!M8))),"", IF(AND('🎯 Palpites (11-20)'!L8='⚽ Jogos'!F7,'🎯 Palpites (11-20)'!M8='⚽ Jogos'!H7),3, IF(AND(SIGN('🎯 Palpites (11-20)'!L8-'🎯 Palpites (11-20)'!M8)=SIGN('⚽ Jogos'!F7-'⚽ Jogos'!H7),('🎯 Palpites (11-20)'!L8-'🎯 Palpites (11-20)'!M8)=('⚽ Jogos'!F7-'⚽ Jogos'!H7)),2, IF(SIGN('🎯 Palpites (11-20)'!L8-'🎯 Palpites (11-20)'!M8)=SIGN('⚽ Jogos'!F7-'⚽ Jogos'!H7),1, 0)))) | S8: =IF(OR(NOT(ISNUMBER('⚽ Jogos'!F7)),NOT(ISNUMBER('⚽ Jogos'!H7)),NOT(ISNUMBER('🎯 Palpites (11-20)'!N8)),NOT(ISNUMBER('🎯 Palpites (11-20)'!O8))),"", IF(AND('🎯 Palpites (11-20)'!N8='⚽ Jogos'!F7,'🎯 Palpites (11-20)'!O8='⚽ Jogos'!H7),3, IF(AND(SIGN('🎯 Palpites (11-20)'!N8-'🎯 Palpites (11-20)'!O8)=SIGN('⚽ Jogos'!F7-'⚽ Jogos'!H7),('🎯 Palpites (11-20)'!N8-'🎯 Palpites (11-20)'!O8)=('⚽ Jogos'!F7-'⚽ Jogos'!H7)),2, IF(SIGN('🎯 Palpites (11-20)'!N8-'🎯 Palpites (11-20)'!O8)=SIGN('⚽ Jogos'!F7-'⚽ Jogos'!H7),1, 0)))) | T8: =IF(OR(NOT(ISNUMBER('⚽ Jogos'!F7)),NOT(ISNUMBER('⚽ Jogos'!H7)),NOT(ISNUMBER('🎯 Palpites (11-20)'!P8)),NOT(ISNUMBER('🎯 Palpites (11-20)'!Q8))),"", IF(AND('🎯 Palpites (11-20)'!P8='⚽ Jogos'!F7,'🎯 Palpites (11-20)'!Q8='⚽ Jogos'!H7),3, IF(AND(SIGN('🎯 Palpites (11-20)'!P8-'🎯 Palpites (11-20)'!Q8)=SIGN('⚽ Jogos'!F7-'⚽ Jogos'!H7),('🎯 Palpites (11-20)'!P8-'🎯 Palpites (11-20)'!Q8)=('⚽ Jogos'!F7-'⚽ Jogos'!H7)),2, IF(SIGN('🎯 Palpites (11-20)'!P8-'🎯 Palpites (11-20)'!Q8)=SIGN('⚽ Jogos'!F7-'⚽ Jogos'!H7),1, 0)))) | U8: =IF(OR(NOT(ISNUMBER('⚽ Jogos'!F7)),NOT(ISNUMBER('⚽ Jogos'!H7)),NOT(ISNUMBER('🎯 Palpites (11-20)'!R8)),NOT(ISNUMBER('🎯 Palpites (11-20)'!S8))),"", IF(AND('🎯 Palpites (11-20)'!R8='⚽ Jogos'!F7,'🎯 Palpites (11-20)'!S8='⚽ Jogos'!H7),3, IF(AND(SIGN('🎯 Palpites (11-20)'!R8-'🎯 Palpites (11-20)'!S8)=SIGN('⚽ Jogos'!F7-'⚽ Jogos'!H7),('🎯 Palpites (11-20)'!R8-'🎯 Palpites (11-20)'!S8)=('⚽ Jogos'!F7-'⚽ Jogos'!H7)),2, IF(SIGN('🎯 Palpites (11-20)'!R8-'🎯 Palpites (11-20)'!S8)=SIGN('⚽ Jogos'!F7-'⚽ Jogos'!H7),1, 0)))) | V8: =IF(OR(NOT(ISNUMBER('⚽ Jogos'!F7)),NOT(ISNUMBER('⚽ Jogos'!H7)),NOT(ISNUMBER('🎯 Palpites (11-20)'!T8)),NOT(ISNUMBER('🎯 Palpites (11-20)'!U8))),"", IF(AND('🎯 Palpites (11-20)'!T8='⚽ Jogos'!F7,'🎯 Palpites (11-20)'!U8='⚽ Jogos'!H7),3, IF(AND(SIGN('🎯 Palpites (11-20)'!T8-'🎯 Palpites (11-20)'!U8)=SIGN('⚽ Jogos'!F7-'⚽ Jogos'!H7),('🎯 Palpites (11-20)'!T8-'🎯 Palpites (11-20)'!U8)=('⚽ Jogos'!F7-'⚽ Jogos'!H7)),2, IF(SIGN('🎯 Palpites (11-20)'!T8-'🎯 Palpites (11-20)'!U8)=SIGN('⚽ Jogos'!F7-'⚽ Jogos'!H7),1, 0)))) | W8: =IF(OR(NOT(ISNUMBER('⚽ Jogos'!F7)),NOT(ISNUMBER('⚽ Jogos'!H7)),NOT(ISNUMBER('🎯 Palpites (11-20)'!V8)),NOT(ISNUMBER('🎯 Palpites (11-20)'!W8))),"", IF(AND('🎯 Palpites (11-20)'!V8='⚽ Jogos'!F7,'🎯 Palpites (11-20)'!W8='⚽ Jogos'!H7),3, IF(AND(SIGN('🎯 Palpites (11-20)'!V8-'🎯 Palpites (11-20)'!W8)=SIGN('⚽ Jogos'!F7-'⚽ Jogos'!H7),('🎯 Palpites (11-20)'!V8-'🎯 Palpites (11-20)'!W8)=('⚽ Jogos'!F7-'⚽ Jogos'!H7)),2, IF(SIGN('🎯 Palpites (11-20)'!V8-'🎯 Palpites (11-20)'!W8)=SIGN('⚽ Jogos'!F7-'⚽ Jogos'!H7),1, 0)))) | X8: =IF(OR(NOT(ISNUMBER('⚽ Jogos'!F7)),NOT(ISNUMBER('⚽ Jogos'!H7)),NOT(ISNUMBER('🎯 Palpites (11-20)'!X8)),NOT(ISNUMBER('🎯 Palpites (11-20)'!Y8))),"", IF(AND('🎯 Palpites (11-20)'!X8='⚽ Jogos'!F7,'🎯 Palpites (11-20)'!Y8='⚽ Jogos'!H7),3, IF(AND(SIGN('🎯 Palpites (11-20)'!X8-'🎯 Palpites (11-20)'!Y8)=SIGN('⚽ Jogos'!F7-'⚽ Jogos'!H7),('🎯 Palpites (11-20)'!X8-'🎯 Palpites (11-20)'!Y8)=('⚽ Jogos'!F7-'⚽ Jogos'!H7)),2, IF(SIGN('🎯 Palpites (11-20)'!X8-'🎯 Palpites (11-20)'!Y8)=SIGN('⚽ Jogos'!F7-'⚽ Jogos'!H7),1, 0))))
B9: 2 | C9: República da Coreia | D9: República Tcheca | E9: =IF(OR(NOT(ISNUMBER('⚽ Jogos'!F8)),NOT(ISNUMBER('⚽ Jogos'!H8)),NOT(ISNUMBER('🎯 Palpites'!F9)),NOT(ISNUMBER('🎯 Palpites'!G9))),"", IF(AND('🎯 Palpites'!F9='⚽ Jogos'!F8,'🎯 Palpites'!G9='⚽ Jogos'!H8),3, IF(AND(SIGN('🎯 Palpites'!F9-'🎯 Palpites'!G9)=SIGN('⚽ Jogos'!F8-'⚽ Jogos'!H8),('🎯 Palpites'!F9-'🎯 Palpites'!G9)=('⚽ Jogos'!F8-'⚽ Jogos'!H8)),2, IF(SIGN('🎯 Palpites'!F9-'🎯 Palpites'!G9)=SIGN('⚽ Jogos'!F8-'⚽ Jogos'!H8),1, 0)))) | F9: =IF(OR(NOT(ISNUMBER('⚽ Jogos'!F8)),NOT(ISNUMBER('⚽ Jogos'!H8)),NOT(ISNUMBER('🎯 Palpites'!H9)),NOT(ISNUMBER('🎯 Palpites'!I9))),"", IF(AND('🎯 Palpites'!H9='⚽ Jogos'!F8,'🎯 Palpites'!I9='⚽ Jogos'!H8),3, IF(AND(SIGN('🎯 Palpites'!H9-'🎯 Palpites'!I9)=SIGN('⚽ Jogos'!F8-'⚽ Jogos'!H8),('🎯 Palpites'!H9-'🎯 Palpites'!I9)=('⚽ Jogos'!F8-'⚽ Jogos'!H8)),2, IF(SIGN('🎯 Palpites'!H9-'🎯 Palpites'!I9)=SIGN('⚽ Jogos'!F8-'⚽ Jogos'!H8),1, 0)))) | G9: =IF(OR(NOT(ISNUMBER('⚽ Jogos'!F8)),NOT(ISNUMBER('⚽ Jogos'!H8)),NOT(ISNUMBER('🎯 Palpites'!J9)),NOT(ISNUMBER('🎯 Palpites'!K9))),"", IF(AND('🎯 Palpites'!J9='⚽ Jogos'!F8,'🎯 Palpites'!K9='⚽ Jogos'!H8),3, IF(AND(SIGN('🎯 Palpites'!J9-'🎯 Palpites'!K9)=SIGN('⚽ Jogos'!F8-'⚽ Jogos'!H8),('🎯 Palpites'!J9-'🎯 Palpites'!K9)=('⚽ Jogos'!F8-'⚽ Jogos'!H8)),2, IF(SIGN('🎯 Palpites'!J9-'🎯 Palpites'!K9)=SIGN('⚽ Jogos'!F8-'⚽ Jogos'!H8),1, 0)))) | H9: =IF(OR(NOT(ISNUMBER('⚽ Jogos'!F8)),NOT(ISNUMBER('⚽ Jogos'!H8)),NOT(ISNUMBER('🎯 Palpites'!L9)),NOT(ISNUMBER('🎯 Palpites'!M9))),"", IF(AND('🎯 Palpites'!L9='⚽ Jogos'!F8,'🎯 Palpites'!M9='⚽ Jogos'!H8),3, IF(AND(SIGN('🎯 Palpites'!L9-'🎯 Palpites'!M9)=SIGN('⚽ Jogos'!F8-'⚽ Jogos'!H8),('🎯 Palpites'!L9-'🎯 Palpites'!M9)=('⚽ Jogos'!F8-'⚽ Jogos'!H8)),2, IF(SIGN('🎯 Palpites'!L9-'🎯 Palpites'!M9)=SIGN('⚽ Jogos'!F8-'⚽ Jogos'!H8),1, 0)))) | I9: =IF(OR(NOT(ISNUMBER('⚽ Jogos'!F8)),NOT(ISNUMBER('⚽ Jogos'!H8)),NOT(ISNUMBER('🎯 Palpites'!N9)),NOT(ISNUMBER('🎯 Palpites'!O9))),"", IF(AND('🎯 Palpites'!N9='⚽ Jogos'!F8,'🎯 Palpites'!O9='⚽ Jogos'!H8),3, IF(AND(SIGN('🎯 Palpites'!N9-'🎯 Palpites'!O9)=SIGN('⚽ Jogos'!F8-'⚽ Jogos'!H8),('🎯 Palpites'!N9-'🎯 Palpites'!O9)=('⚽ Jogos'!F8-'⚽ Jogos'!H8)),2, IF(SIGN('🎯 Palpites'!N9-'🎯 Palpites'!O9)=SIGN('⚽ Jogos'!F8-'⚽ Jogos'!H8),1, 0)))) | J9: =IF(OR(NOT(ISNUMBER('⚽ Jogos'!F8)),NOT(ISNUMBER('⚽ Jogos'!H8)),NOT(ISNUMBER('🎯 Palpites'!P9)),NOT(ISNUMBER('🎯 Palpites'!Q9))),"", IF(AND('🎯 Palpites'!P9='⚽ Jogos'!F8,'🎯 Palpites'!Q9='⚽ Jogos'!H8),3, IF(AND(SIGN('🎯 Palpites'!P9-'🎯 Palpites'!Q9)=SIGN('⚽ Jogos'!F8-'⚽ Jogos'!H8),('🎯 Palpites'!P9-'🎯 Palpites'!Q9)=('⚽ Jogos'!F8-'⚽ Jogos'!H8)),2, IF(SIGN('🎯 Palpites'!P9-'🎯 Palpites'!Q9)=SIGN('⚽ Jogos'!F8-'⚽ Jogos'!H8),1, 0)))) | K9: =IF(OR(NOT(ISNUMBER('⚽ Jogos'!F8)),NOT(ISNUMBER('⚽ Jogos'!H8)),NOT(ISNUMBER('🎯 Palpites'!R9)),NOT(ISNUMBER('🎯 Palpites'!S9))),"", IF(AND('🎯 Palpites'!R9='⚽ Jogos'!F8,'🎯 Palpites'!S9='⚽ Jogos'!H8),3, IF(AND(SIGN('🎯 Palpites'!R9-'🎯 Palpites'!S9)=SIGN('⚽ Jogos'!F8-'⚽ Jogos'!H8),('🎯 Palpites'!R9-'🎯 Palpites'!S9)=('⚽ Jogos'!F8-'⚽ Jogos'!H8)),2, IF(SIGN('🎯 Palpites'!R9-'🎯 Palpites'!S9)=SIGN('⚽ Jogos'!F8-'⚽ Jogos'!H8),1, 0)))) | L9: =IF(OR(NOT(ISNUMBER('⚽ Jogos'!F8)),NOT(ISNUMBER('⚽ Jogos'!H8)),NOT(ISNUMBER('🎯 Palpites'!T9)),NOT(ISNUMBER('🎯 Palpites'!U9))),"", IF(AND('🎯 Palpites'!T9='⚽ Jogos'!F8,'🎯 Palpites'!U9='⚽ Jogos'!H8),3, IF(AND(SIGN('🎯 Palpites'!T9-'🎯 Palpites'!U9)=SIGN('⚽ Jogos'!F8-'⚽ Jogos'!H8),('🎯 Palpites'!T9-'🎯 Palpites'!U9)=('⚽ Jogos'!F8-'⚽ Jogos'!H8)),2, IF(SIGN('🎯 Palpites'!T9-'🎯 Palpites'!U9)=SIGN('⚽ Jogos'!F8-'⚽ Jogos'!H8),1, 0)))) | M9: =IF(OR(NOT(ISNUMBER('⚽ Jogos'!F8)),NOT(ISNUMBER('⚽ Jogos'!H8)),NOT(ISNUMBER('🎯 Palpites'!V9)),NOT(ISNUMBER('🎯 Palpites'!W9))),"", IF(AND('🎯 Palpites'!V9='⚽ Jogos'!F8,'🎯 Palpites'!W9='⚽ Jogos'!H8),3, IF(AND(SIGN('🎯 Palpites'!V9-'🎯 Palpites'!W9)=SIGN('⚽ Jogos'!F8-'⚽ Jogos'!H8),('🎯 Palpites'!V9-'🎯 Palpites'!W9)=('⚽ Jogos'!F8-'⚽ Jogos'!H8)),2, IF(SIGN('🎯 Palpites'!V9-'🎯 Palpites'!W9)=SIGN('⚽ Jogos'!F8-'⚽ Jogos'!H8),1, 0)))) | N9: =IF(OR(NOT(ISNUMBER('⚽ Jogos'!F8)),NOT(ISNUMBER('⚽ Jogos'!H8)),NOT(ISNUMBER('🎯 Palpites'!X9)),NOT(ISNUMBER('🎯 Palpites'!Y9))),"", IF(AND('🎯 Palpites'!X9='⚽ Jogos'!F8,'🎯 Palpites'!Y9='⚽ Jogos'!H8),3, IF(AND(SIGN('🎯 Palpites'!X9-'🎯 Palpites'!Y9)=SIGN('⚽ Jogos'!F8-'⚽ Jogos'!H8),('🎯 Palpites'!X9-'🎯 Palpites'!Y9)=('⚽ Jogos'!F8-'⚽ Jogos'!H8)),2, IF(SIGN('🎯 Palpites'!X9-'🎯 Palpites'!Y9)=SIGN('⚽ Jogos'!F8-'⚽ Jogos'!H8),1, 0)))) | O9: =IF(OR(NOT(ISNUMBER('⚽ Jogos'!F8)),NOT(ISNUMBER('⚽ Jogos'!H8)),NOT(ISNUMBER('🎯 Palpites (11-20)'!F9)),NOT(ISNUMBER('🎯 Palpites (11-20)'!G9))),"", IF(AND('🎯 Palpites (11-20)'!F9='⚽ Jogos'!F8,'🎯 Palpites (11-20)'!G9='⚽ Jogos'!H8),3, IF(AND(SIGN('🎯 Palpites (11-20)'!F9-'🎯 Palpites (11-20)'!G9)=SIGN('⚽ Jogos'!F8-'⚽ Jogos'!H8),('🎯 Palpites (11-20)'!F9-'🎯 Palpites (11-20)'!G9)=('⚽ Jogos'!F8-'⚽ Jogos'!H8)),2, IF(SIGN('🎯 Palpites (11-20)'!F9-'🎯 Palpites (11-20)'!G9)=SIGN('⚽ Jogos'!F8-'⚽ Jogos'!H8),1, 0)))) | P9: =IF(OR(NOT(ISNUMBER('⚽ Jogos'!F8)),NOT(ISNUMBER('⚽ Jogos'!H8)),NOT(ISNUMBER('🎯 Palpites (11-20)'!H9)),NOT(ISNUMBER('🎯 Palpites (11-20)'!I9))),"", IF(AND('🎯 Palpites (11-20)'!H9='⚽ Jogos'!F8,'🎯 Palpites (11-20)'!I9='⚽ Jogos'!H8),3, IF(AND(SIGN('🎯 Palpites (11-20)'!H9-'🎯 Palpites (11-20)'!I9)=SIGN('⚽ Jogos'!F8-'⚽ Jogos'!H8),('🎯 Palpites (11-20)'!H9-'🎯 Palpites (11-20)'!I9)=('⚽ Jogos'!F8-'⚽ Jogos'!H8)),2, IF(SIGN('🎯 Palpites (11-20)'!H9-'🎯 Palpites (11-20)'!I9)=SIGN('⚽ Jogos'!F8-'⚽ Jogos'!H8),1, 0)))) | Q9: =IF(OR(NOT(ISNUMBER('⚽ Jogos'!F8)),NOT(ISNUMBER('⚽ Jogos'!H8)),NOT(ISNUMBER('🎯 Palpites (11-20)'!J9)),NOT(ISNUMBER('🎯 Palpites (11-20)'!K9))),"", IF(AND('🎯 Palpites (11-20)'!J9='⚽ Jogos'!F8,'🎯 Palpites (11-20)'!K9='⚽ Jogos'!H8),3, IF(AND(SIGN('🎯 Palpites (11-20)'!J9-'🎯 Palpites (11-20)'!K9)=SIGN('⚽ Jogos'!F8-'⚽ Jogos'!H8),('🎯 Palpites (11-20)'!J9-'🎯 Palpites (11-20)'!K9)=('⚽ Jogos'!F8-'⚽ Jogos'!H8)),2, IF(SIGN('🎯 Palpites (11-20)'!J9-'🎯 Palpites (11-20)'!K9)=SIGN('⚽ Jogos'!F8-'⚽ Jogos'!H8),1, 0)))) | R9: =IF(OR(NOT(ISNUMBER('⚽ Jogos'!F8)),NOT(ISNUMBER('⚽ Jogos'!H8)),NOT(ISNUMBER('🎯 Palpites (11-20)'!L9)),NOT(ISNUMBER('🎯 Palpites (11-20)'!M9))),"", IF(AND('🎯 Palpites (11-20)'!L9='⚽ Jogos'!F8,'🎯 Palpites (11-20)'!M9='⚽ Jogos'!H8),3, IF(AND(SIGN('🎯 Palpites (11-20)'!L9-'🎯 Palpites (11-20)'!M9)=SIGN('⚽ Jogos'!F8-'⚽ Jogos'!H8),('🎯 Palpites (11-20)'!L9-'🎯 Palpites (11-20)'!M9)=('⚽ Jogos'!F8-'⚽ Jogos'!H8)),2, IF(SIGN('🎯 Palpites (11-20)'!L9-'🎯 Palpites (11-20)'!M9)=SIGN('⚽ Jogos'!F8-'⚽ Jogos'!H8),1, 0)))) | S9: =IF(OR(NOT(ISNUMBER('⚽ Jogos'!F8)),NOT(ISNUMBER('⚽ Jogos'!H8)),NOT(ISNUMBER('🎯 Palpites (11-20)'!N9)),NOT(ISNUMBER('🎯 Palpites (11-20)'!O9))),"", IF(AND('🎯 Palpites (11-20)'!N9='⚽ Jogos'!F8,'🎯 Palpites (11-20)'!O9='⚽ Jogos'!H8),3, IF(AND(SIGN('🎯 Palpites (11-20)'!N9-'🎯 Palpites (11-20)'!O9)=SIGN('⚽ Jogos'!F8-'⚽ Jogos'!H8),('🎯 Palpites (11-20)'!N9-'🎯 Palpites (11-20)'!O9)=('⚽ Jogos'!F8-'⚽ Jogos'!H8)),2, IF(SIGN('🎯 Palpites (11-20)'!N9-'🎯 Palpites (11-20)'!O9)=SIGN('⚽ Jogos'!F8-'⚽ Jogos'!H8),1, 0)))) | T9: =IF(OR(NOT(ISNUMBER('⚽ Jogos'!F8)),NOT(ISNUMBER('⚽ Jogos'!H8)),NOT(ISNUMBER('🎯 Palpites (11-20)'!P9)),NOT(ISNUMBER('🎯 Palpites (11-20)'!Q9))),"", IF(AND('🎯 Palpites (11-20)'!P9='⚽ Jogos'!F8,'🎯 Palpites (11-20)'!Q9='⚽ Jogos'!H8),3, IF(AND(SIGN('🎯 Palpites (11-20)'!P9-'🎯 Palpites (11-20)'!Q9)=SIGN('⚽ Jogos'!F8-'⚽ Jogos'!H8),('🎯 Palpites (11-20)'!P9-'🎯 Palpites (11-20)'!Q9)=('⚽ Jogos'!F8-'⚽ Jogos'!H8)),2, IF(SIGN('🎯 Palpites (11-20)'!P9-'🎯 Palpites (11-20)'!Q9)=SIGN('⚽ Jogos'!F8-'⚽ Jogos'!H8),1, 0)))) | U9: =IF(OR(NOT(ISNUMBER('⚽ Jogos'!F8)),NOT(ISNUMBER('⚽ Jogos'!H8)),NOT(ISNUMBER('🎯 Palpites (11-20)'!R9)),NOT(ISNUMBER('🎯 Palpites (11-20)'!S9))),"", IF(AND('🎯 Palpites (11-20)'!R9='⚽ Jogos'!F8,'🎯 Palpites (11-20)'!S9='⚽ Jogos'!H8),3, IF(AND(SIGN('🎯 Palpites (11-20)'!R9-'🎯 Palpites (11-20)'!S9)=SIGN('⚽ Jogos'!F8-'⚽ Jogos'!H8),('🎯 Palpites (11-20)'!R9-'🎯 Palpites (11-20)'!S9)=('⚽ Jogos'!F8-'⚽ Jogos'!H8)),2, IF(SIGN('🎯 Palpites (11-20)'!R9-'🎯 Palpites (11-20)'!S9)=SIGN('⚽ Jogos'!F8-'⚽ Jogos'!H8),1, 0)))) | V9: =IF(OR(NOT(ISNUMBER('⚽ Jogos'!F8)),NOT(ISNUMBER('⚽ Jogos'!H8)),NOT(ISNUMBER('🎯 Palpites (11-20)'!T9)),NOT(ISNUMBER('🎯 Palpites (11-20)'!U9))),"", IF(AND('🎯 Palpites (11-20)'!T9='⚽ Jogos'!F8,'🎯 Palpites (11-20)'!U9='⚽ Jogos'!H8),3, IF(AND(SIGN('🎯 Palpites (11-20)'!T9-'🎯 Palpites (11-20)'!U9)=SIGN('⚽ Jogos'!F8-'⚽ Jogos'!H8),('🎯 Palpites (11-20)'!T9-'🎯 Palpites (11-20)'!U9)=('⚽ Jogos'!F8-'⚽ Jogos'!H8)),2, IF(SIGN('🎯 Palpites (11-20)'!T9-'🎯 Palpites (11-20)'!U9)=SIGN('⚽ Jogos'!F8-'⚽ Jogos'!H8),1, 0)))) | W9: =IF(OR(NOT(ISNUMBER('⚽ Jogos'!F8)),NOT(ISNUMBER('⚽ Jogos'!H8)),NOT(ISNUMBER('🎯 Palpites (11-20)'!V9)),NOT(ISNUMBER('🎯 Palpites (11-20)'!W9))),"", IF(AND('🎯 Palpites (11-20)'!V9='⚽ Jogos'!F8,'🎯 Palpites (11-20)'!W9='⚽ Jogos'!H8),3, IF(AND(SIGN('🎯 Palpites (11-20)'!V9-'🎯 Palpites (11-20)'!W9)=SIGN('⚽ Jogos'!F8-'⚽ Jogos'!H8),('🎯 Palpites (11-20)'!V9-'🎯 Palpites (11-20)'!W9)=('⚽ Jogos'!F8-'⚽ Jogos'!H8)),2, IF(SIGN('🎯 Palpites (11-20)'!V9-'🎯 Palpites (11-20)'!W9)=SIGN('⚽ Jogos'!F8-'⚽ Jogos'!H8),1, 0)))) | X9: =IF(OR(NOT(ISNUMBER('⚽ Jogos'!F8)),NOT(ISNUMBER('⚽ Jogos'!H8)),NOT(ISNUMBER('🎯 Palpites (11-20)'!X9)),NOT(ISNUMBER('🎯 Palpites (11-20)'!Y9))),"", IF(AND('🎯 Palpites (11-20)'!X9='⚽ Jogos'!F8,'🎯 Palpites (11-20)'!Y9='⚽ Jogos'!H8),3, IF(AND(SIGN('🎯 Palpites (11-20)'!X9-'🎯 Palpites (11-20)'!Y9)=SIGN('⚽ Jogos'!F8-'⚽ Jogos'!H8),('🎯 Palpites (11-20)'!X9-'🎯 Palpites (11-20)'!Y9)=('⚽ Jogos'!F8-'⚽ Jogos'!H8)),2, IF(SIGN('🎯 Palpites (11-20)'!X9-'🎯 Palpites (11-20)'!Y9)=SIGN('⚽ Jogos'!F8-'⚽ Jogos'!H8),1, 0))))
B10: 3 | C10: Canadá | D10: Bósnia e Herzegovina | E10: =IF(OR(NOT(ISNUMBER('⚽ Jogos'!F9)),NOT(ISNUMBER('⚽ Jogos'!H9)),NOT(ISNUMBER('🎯 Palpites'!F10)),NOT(ISNUMBER('🎯 Palpites'!G10))),"", IF(AND('🎯 Palpites'!F10='⚽ Jogos'!F9,'🎯 Palpites'!G10='⚽ Jogos'!H9),3, IF(AND(SIGN('🎯 Palpites'!F10-'🎯 Palpites'!G10)=SIGN('⚽ Jogos'!F9-'⚽ Jogos'!H9),('🎯 Palpites'!F10-'🎯 Palpites'!G10)=('⚽ Jogos'!F9-'⚽ Jogos'!H9)),2, IF(SIGN('🎯 Palpites'!F10-'🎯 Palpites'!G10)=SIGN('⚽ Jogos'!F9-'⚽ Jogos'!H9),1, 0)))) | F10: =IF(OR(NOT(ISNUMBER('⚽ Jogos'!F9)),NOT(ISNUMBER('⚽ Jogos'!H9)),NOT(ISNUMBER('🎯 Palpites'!H10)),NOT(ISNUMBER('🎯 Palpites'!I10))),"", IF(AND('🎯 Palpites'!H10='⚽ Jogos'!F9,'🎯 Palpites'!I10='⚽ Jogos'!H9),3, IF(AND(SIGN('🎯 Palpites'!H10-'🎯 Palpites'!I10)=SIGN('⚽ Jogos'!F9-'⚽ Jogos'!H9),('🎯 Palpites'!H10-'🎯 Palpites'!I10)=('⚽ Jogos'!F9-'⚽ Jogos'!H9)),2, IF(SIGN('🎯 Palpites'!H10-'🎯 Palpites'!I10)=SIGN('⚽ Jogos'!F9-'⚽ Jogos'!H9),1, 0)))) | G10: =IF(OR(NOT(ISNUMBER('⚽ Jogos'!F9)),NOT(ISNUMBER('⚽ Jogos'!H9)),NOT(ISNUMBER('🎯 Palpites'!J10)),NOT(ISNUMBER('🎯 Palpites'!K10))),"", IF(AND('🎯 Palpites'!J10='⚽ Jogos'!F9,'🎯 Palpites'!K10='⚽ Jogos'!H9),3, IF(AND(SIGN('🎯 Palpites'!J10-'🎯 Palpites'!K10)=SIGN('⚽ Jogos'!F9-'⚽ Jogos'!H9),('🎯 Palpites'!J10-'🎯 Palpites'!K10)=('⚽ Jogos'!F9-'⚽ Jogos'!H9)),2, IF(SIGN('🎯 Palpites'!J10-'🎯 Palpites'!K10)=SIGN('⚽ Jogos'!F9-'⚽ Jogos'!H9),1, 0)))) | H10: =IF(OR(NOT(ISNUMBER('⚽ Jogos'!F9)),NOT(ISNUMBER('⚽ Jogos'!H9)),NOT(ISNUMBER('🎯 Palpites'!L10)),NOT(ISNUMBER('🎯 Palpites'!M10))),"", IF(AND('🎯 Palpites'!L10='⚽ Jogos'!F9,'🎯 Palpites'!M10='⚽ Jogos'!H9),3, IF(AND(SIGN('🎯 Palpites'!L10-'🎯 Palpites'!M10)=SIGN('⚽ Jogos'!F9-'⚽ Jogos'!H9),('🎯 Palpites'!L10-'🎯 Palpites'!M10)=('⚽ Jogos'!F9-'⚽ Jogos'!H9)),2, IF(SIGN('🎯 Palpites'!L10-'🎯 Palpites'!M10)=SIGN('⚽ Jogos'!F9-'⚽ Jogos'!H9),1, 0)))) | I10: =IF(OR(NOT(ISNUMBER('⚽ Jogos'!F9)),NOT(ISNUMBER('⚽ Jogos'!H9)),NOT(ISNUMBER('🎯 Palpites'!N10)),NOT(ISNUMBER('🎯 Palpites'!O10))),"", IF(AND('🎯 Palpites'!N10='⚽ Jogos'!F9,'🎯 Palpites'!O10='⚽ Jogos'!H9),3, IF(AND(SIGN('🎯 Palpites'!N10-'🎯 Palpites'!O10)=SIGN('⚽ Jogos'!F9-'⚽ Jogos'!H9),('🎯 Palpites'!N10-'🎯 Palpites'!O10)=('⚽ Jogos'!F9-'⚽ Jogos'!H9)),2, IF(SIGN('🎯 Palpites'!N10-'🎯 Palpites'!O10)=SIGN('⚽ Jogos'!F9-'⚽ Jogos'!H9),1, 0)))) | J10: =IF(OR(NOT(ISNUMBER('⚽ Jogos'!F9)),NOT(ISNUMBER('⚽ Jogos'!H9)),NOT(ISNUMBER('🎯 Palpites'!P10)),NOT(ISNUMBER('🎯 Palpites'!Q10))),"", IF(AND('🎯 Palpites'!P10='⚽ Jogos'!F9,'🎯 Palpites'!Q10='⚽ Jogos'!H9),3, IF(AND(SIGN('🎯 Palpites'!P10-'🎯 Palpites'!Q10)=SIGN('⚽ Jogos'!F9-'⚽ Jogos'!H9),('🎯 Palpites'!P10-'🎯 Palpites'!Q10)=('⚽ Jogos'!F9-'⚽ Jogos'!H9)),2, IF(SIGN('🎯 Palpites'!P10-'🎯 Palpites'!Q10)=SIGN('⚽ Jogos'!F9-'⚽ Jogos'!H9),1, 0)))) | K10: =IF(OR(NOT(ISNUMBER('⚽ Jogos'!F9)),NOT(ISNUMBER('⚽ Jogos'!H9)),NOT(ISNUMBER('🎯 Palpites'!R10)),NOT(ISNUMBER('🎯 Palpites'!S10))),"", IF(AND('🎯 Palpites'!R10='⚽ Jogos'!F9,'🎯 Palpites'!S10='⚽ Jogos'!H9),3, IF(AND(SIGN('🎯 Palpites'!R10-'🎯 Palpites'!S10)=SIGN('⚽ Jogos'!F9-'⚽ Jogos'!H9),('🎯 Palpites'!R10-'🎯 Palpites'!S10)=('⚽ Jogos'!F9-'⚽ Jogos'!H9)),2, IF(SIGN('🎯 Palpites'!R10-'🎯 Palpites'!S10)=SIGN('⚽ Jogos'!F9-'⚽ Jogos'!H9),1, 0)))) | L10: =IF(OR(NOT(ISNUMBER('⚽ Jogos'!F9)),NOT(ISNUMBER('⚽ Jogos'!H9)),NOT(ISNUMBER('🎯 Palpites'!T10)),NOT(ISNUMBER('🎯 Palpites'!U10))),"", IF(AND('🎯 Palpites'!T10='⚽ Jogos'!F9,'🎯 Palpites'!U10='⚽ Jogos'!H9),3, IF(AND(SIGN('🎯 Palpites'!T10-'🎯 Palpites'!U10)=SIGN('⚽ Jogos'!F9-'⚽ Jogos'!H9),('🎯 Palpites'!T10-'🎯 Palpites'!U10)=('⚽ Jogos'!F9-'⚽ Jogos'!H9)),2, IF(SIGN('🎯 Palpites'!T10-'🎯 Palpites'!U10)=SIGN('⚽ Jogos'!F9-'⚽ Jogos'!H9),1, 0)))) | M10: =IF(OR(NOT(ISNUMBER('⚽ Jogos'!F9)),NOT(ISNUMBER('⚽ Jogos'!H9)),NOT(ISNUMBER('🎯 Palpites'!V10)),NOT(ISNUMBER('🎯 Palpites'!W10))),"", IF(AND('🎯 Palpites'!V10='⚽ Jogos'!F9,'🎯 Palpites'!W10='⚽ Jogos'!H9),3, IF(AND(SIGN('🎯 Palpites'!V10-'🎯 Palpites'!W10)=SIGN('⚽ Jogos'!F9-'⚽ Jogos'!H9),('🎯 Palpites'!V10-'🎯 Palpites'!W10)=('⚽ Jogos'!F9-'⚽ Jogos'!H9)),2, IF(SIGN('🎯 Palpites'!V10-'🎯 Palpites'!W10)=SIGN('⚽ Jogos'!F9-'⚽ Jogos'!H9),1, 0)))) | N10: =IF(OR(NOT(ISNUMBER('⚽ Jogos'!F9)),NOT(ISNUMBER('⚽ Jogos'!H9)),NOT(ISNUMBER('🎯 Palpites'!X10)),NOT(ISNUMBER('🎯 Palpites'!Y10))),"", IF(AND('🎯 Palpites'!X10='⚽ Jogos'!F9,'🎯 Palpites'!Y10='⚽ Jogos'!H9),3, IF(AND(SIGN('🎯 Palpites'!X10-'🎯 Palpites'!Y10)=SIGN('⚽ Jogos'!F9-'⚽ Jogos'!H9),('🎯 Palpites'!X10-'🎯 Palpites'!Y10)=('⚽ Jogos'!F9-'⚽ Jogos'!H9)),2, IF(SIGN('🎯 Palpites'!X10-'🎯 Palpites'!Y10)=SIGN('⚽ Jogos'!F9-'⚽ Jogos'!H9),1, 0)))) | O10: =IF(OR(NOT(ISNUMBER('⚽ Jogos'!F9)),NOT(ISNUMBER('⚽ Jogos'!H9)),NOT(ISNUMBER('🎯 Palpites (11-20)'!F10)),NOT(ISNUMBER('🎯 Palpites (11-20)'!G10))),"", IF(AND('🎯 Palpites (11-20)'!F10='⚽ Jogos'!F9,'🎯 Palpites (11-20)'!G10='⚽ Jogos'!H9),3, IF(AND(SIGN('🎯 Palpites (11-20)'!F10-'🎯 Palpites (11-20)'!G10)=SIGN('⚽ Jogos'!F9-'⚽ Jogos'!H9),('🎯 Palpites (11-20)'!F10-'🎯 Palpites (11-20)'!G10)=('⚽ Jogos'!F9-'⚽ Jogos'!H9)),2, IF(SIGN('🎯 Palpites (11-20)'!F10-'🎯 Palpites (11-20)'!G10)=SIGN('⚽ Jogos'!F9-'⚽ Jogos'!H9),1, 0)))) | P10: =IF(OR(NOT(ISNUMBER('⚽ Jogos'!F9)),NOT(ISNUMBER('⚽ Jogos'!H9)),NOT(ISNUMBER('🎯 Palpites (11-20)'!H10)),NOT(ISNUMBER('🎯 Palpites (11-20)'!I10))),"", IF(AND('🎯 Palpites (11-20)'!H10='⚽ Jogos'!F9,'🎯 Palpites (11-20)'!I10='⚽ Jogos'!H9),3, IF(AND(SIGN('🎯 Palpites (11-20)'!H10-'🎯 Palpites (11-20)'!I10)=SIGN('⚽ Jogos'!F9-'⚽ Jogos'!H9),('🎯 Palpites (11-20)'!H10-'🎯 Palpites (11-20)'!I10)=('⚽ Jogos'!F9-'⚽ Jogos'!H9)),2, IF(SIGN('🎯 Palpites (11-20)'!H10-'🎯 Palpites (11-20)'!I10)=SIGN('⚽ Jogos'!F9-'⚽ Jogos'!H9),1, 0)))) | Q10: =IF(OR(NOT(ISNUMBER('⚽ Jogos'!F9)),NOT(ISNUMBER('⚽ Jogos'!H9)),NOT(ISNUMBER('🎯 Palpites (11-20)'!J10)),NOT(ISNUMBER('🎯 Palpites (11-20)'!K10))),"", IF(AND('🎯 Palpites (11-20)'!J10='⚽ Jogos'!F9,'🎯 Palpites (11-20)'!K10='⚽ Jogos'!H9),3, IF(AND(SIGN('🎯 Palpites (11-20)'!J10-'🎯 Palpites (11-20)'!K10)=SIGN('⚽ Jogos'!F9-'⚽ Jogos'!H9),('🎯 Palpites (11-20)'!J10-'🎯 Palpites (11-20)'!K10)=('⚽ Jogos'!F9-'⚽ Jogos'!H9)),2, IF(SIGN('🎯 Palpites (11-20)'!J10-'🎯 Palpites (11-20)'!K10)=SIGN('⚽ Jogos'!F9-'⚽ Jogos'!H9),1, 0)))) | R10: =IF(OR(NOT(ISNUMBER('⚽ Jogos'!F9)),NOT(ISNUMBER('⚽ Jogos'!H9)),NOT(ISNUMBER('🎯 Palpites (11-20)'!L10)),NOT(ISNUMBER('🎯 Palpites (11-20)'!M10))),"", IF(AND('🎯 Palpites (11-20)'!L10='⚽ Jogos'!F9,'🎯 Palpites (11-20)'!M10='⚽ Jogos'!H9),3, IF(AND(SIGN('🎯 Palpites (11-20)'!L10-'🎯 Palpites (11-20)'!M10)=SIGN('⚽ Jogos'!F9-'⚽ Jogos'!H9),('🎯 Palpites (11-20)'!L10-'🎯 Palpites (11-20)'!M10)=('⚽ Jogos'!F9-'⚽ Jogos'!H9)),2, IF(SIGN('🎯 Palpites (11-20)'!L10-'🎯 Palpites (11-20)'!M10)=SIGN('⚽ Jogos'!F9-'⚽ Jogos'!H9),1, 0)))) | S10: =IF(OR(NOT(ISNUMBER('⚽ Jogos'!F9)),NOT(ISNUMBER('⚽ Jogos'!H9)),NOT(ISNUMBER('🎯 Palpites (11-20)'!N10)),NOT(ISNUMBER('🎯 Palpites (11-20)'!O10))),"", IF(AND('🎯 Palpites (11-20)'!N10='⚽ Jogos'!F9,'🎯 Palpites (11-20)'!O10='⚽ Jogos'!H9),3, IF(AND(SIGN('🎯 Palpites (11-20)'!N10-'🎯 Palpites (11-20)'!O10)=SIGN('⚽ Jogos'!F9-'⚽ Jogos'!H9),('🎯 Palpites (11-20)'!N10-'🎯 Palpites (11-20)'!O10)=('⚽ Jogos'!F9-'⚽ Jogos'!H9)),2, IF(SIGN('🎯 Palpites (11-20)'!N10-'🎯 Palpites (11-20)'!O10)=SIGN('⚽ Jogos'!F9-'⚽ Jogos'!H9),1, 0)))) | T10: =IF(OR(NOT(ISNUMBER('⚽ Jogos'!F9)),NOT(ISNUMBER('⚽ Jogos'!H9)),NOT(ISNUMBER('🎯 Palpites (11-20)'!P10)),NOT(ISNUMBER('🎯 Palpites (11-20)'!Q10))),"", IF(AND('🎯 Palpites (11-20)'!P10='⚽ Jogos'!F9,'🎯 Palpites (11-20)'!Q10='⚽ Jogos'!H9),3, IF(AND(SIGN('🎯 Palpites (11-20)'!P10-'🎯 Palpites (11-20)'!Q10)=SIGN('⚽ Jogos'!F9-'⚽ Jogos'!H9),('🎯 Palpites (11-20)'!P10-'🎯 Palpites (11-20)'!Q10)=('⚽ Jogos'!F9-'⚽ Jogos'!H9)),2, IF(SIGN('🎯 Palpites (11-20)'!P10-'🎯 Palpites (11-20)'!Q10)=SIGN('⚽ Jogos'!F9-'⚽ Jogos'!H9),1, 0)))) | U10: =IF(OR(NOT(ISNUMBER('⚽ Jogos'!F9)),NOT(ISNUMBER('⚽ Jogos'!H9)),NOT(ISNUMBER('🎯 Palpites (11-20)'!R10)),NOT(ISNUMBER('🎯 Palpites (11-20)'!S10))),"", IF(AND('🎯 Palpites (11-20)'!R10='⚽ Jogos'!F9,'🎯 Palpites (11-20)'!S10='⚽ Jogos'!H9),3, IF(AND(SIGN('🎯 Palpites (11-20)'!R10-'🎯 Palpites (11-20)'!S10)=SIGN('⚽ Jogos'!F9-'⚽ Jogos'!H9),('🎯 Palpites (11-20)'!R10-'🎯 Palpites (11-20)'!S10)=('⚽ Jogos'!F9-'⚽ Jogos'!H9)),2, IF(SIGN('🎯 Palpites (11-20)'!R10-'🎯 Palpites (11-20)'!S10)=SIGN('⚽ Jogos'!F9-'⚽ Jogos'!H9),1, 0)))) | V10: =IF(OR(NOT(ISNUMBER('⚽ Jogos'!F9)),NOT(ISNUMBER('⚽ Jogos'!H9)),NOT(ISNUMBER('🎯 Palpites (11-20)'!T10)),NOT(ISNUMBER('🎯 Palpites (11-20)'!U10))),"", IF(AND('🎯 Palpites (11-20)'!T10='⚽ Jogos'!F9,'🎯 Palpites (11-20)'!U10='⚽ Jogos'!H9),3, IF(AND(SIGN('🎯 Palpites (11-20)'!T10-'🎯 Palpites (11-20)'!U10)=SIGN('⚽ Jogos'!F9-'⚽ Jogos'!H9),('🎯 Palpites (11-20)'!T10-'🎯 Palpites (11-20)'!U10)=('⚽ Jogos'!F9-'⚽ Jogos'!H9)),2, IF(SIGN('🎯 Palpites (11-20)'!T10-'🎯 Palpites (11-20)'!U10)=SIGN('⚽ Jogos'!F9-'⚽ Jogos'!H9),1, 0)))) | W10: =IF(OR(NOT(ISNUMBER('⚽ Jogos'!F9)),NOT(ISNUMBER('⚽ Jogos'!H9)),NOT(ISNUMBER('🎯 Palpites (11-20)'!V10)),NOT(ISNUMBER('🎯 Palpites (11-20)'!W10))),"", IF(AND('🎯 Palpites (11-20)'!V10='⚽ Jogos'!F9,'🎯 Palpites (11-20)'!W10='⚽ Jogos'!H9),3, IF(AND(SIGN('🎯 Palpites (11-20)'!V10-'🎯 Palpites (11-20)'!W10)=SIGN('⚽ Jogos'!F9-'⚽ Jogos'!H9),('🎯 Palpites (11-20)'!V10-'🎯 Palpites (11-20)'!W10)=('⚽ Jogos'!F9-'⚽ Jogos'!H9)),2, IF(SIGN('🎯 Palpites (11-20)'!V10-'🎯 Palpites (11-20)'!W10)=SIGN('⚽ Jogos'!F9-'⚽ Jogos'!H9),1, 0)))) | X10: =IF(OR(NOT(ISNUMBER('⚽ Jogos'!F9)),NOT(ISNUMBER('⚽ Jogos'!H9)),NOT(ISNUMBER('🎯 Palpites (11-20)'!X10)),NOT(ISNUMBER('🎯 Palpites (11-20)'!Y10))),"", IF(AND('🎯 Palpites (11-20)'!X10='⚽ Jogos'!F9,'🎯 Palpites (11-20)'!Y10='⚽ Jogos'!H9),3, IF(AND(SIGN('🎯 Palpites (11-20)'!X10-'🎯 Palpites (11-20)'!Y10)=SIGN('⚽ Jogos'!F9-'⚽ Jogos'!H9),('🎯 Palpites (11-20)'!X10-'🎯 Palpites (11-20)'!Y10)=('⚽ Jogos'!F9-'⚽ Jogos'!H9)),2, IF(SIGN('🎯 Palpites (11-20)'!X10-'🎯 Palpites (11-20)'!Y10)=SIGN('⚽ Jogos'!F9-'⚽ Jogos'!H9),1, 0))))
B11: 4 | C11: Estados Unidos | D11: Paraguai | E11: =IF(OR(NOT(ISNUMBER('⚽ Jogos'!F10)),NOT(ISNUMBER('⚽ Jogos'!H10)),NOT(ISNUMBER('🎯 Palpites'!F11)),NOT(ISNUMBER('🎯 Palpites'!G11))),"", IF(AND('🎯 Palpites'!F11='⚽ Jogos'!F10,'🎯 Palpites'!G11='⚽ Jogos'!H10),3, IF(AND(SIGN('🎯 Palpites'!F11-'🎯 Palpites'!G11)=SIGN('⚽ Jogos'!F10-'⚽ Jogos'!H10),('🎯 Palpites'!F11-'🎯 Palpites'!G11)=('⚽ Jogos'!F10-'⚽ Jogos'!H10)),2, IF(SIGN('🎯 Palpites'!F11-'🎯 Palpites'!G11)=SIGN('⚽ Jogos'!F10-'⚽ Jogos'!H10),1, 0)))) | F11: =IF(OR(NOT(ISNUMBER('⚽ Jogos'!F10)),NOT(ISNUMBER('⚽ Jogos'!H10)),NOT(ISNUMBER('🎯 Palpites'!H11)),NOT(ISNUMBER('🎯 Palpites'!I11))),"", IF(AND('🎯 Palpites'!H11='⚽ Jogos'!F10,'🎯 Palpites'!I11='⚽ Jogos'!H10),3, IF(AND(SIGN('🎯 Palpites'!H11-'🎯 Palpites'!I11)=SIGN('⚽ Jogos'!F10-'⚽ Jogos'!H10),('🎯 Palpites'!H11-'🎯 Palpites'!I11)=('⚽ Jogos'!F10-'⚽ Jogos'!H10)),2, IF(SIGN('🎯 Palpites'!H11-'🎯 Palpites'!I11)=SIGN('⚽ Jogos'!F10-'⚽ Jogos'!H10),1, 0)))) | G11: =IF(OR(NOT(ISNUMBER('⚽ Jogos'!F10)),NOT(ISNUMBER('⚽ Jogos'!H10)),NOT(ISNUMBER('🎯 Palpites'!J11)),NOT(ISNUMBER('🎯 Palpites'!K11))),"", IF(AND('🎯 Palpites'!J11='⚽ Jogos'!F10,'🎯 Palpites'!K11='⚽ Jogos'!H10),3, IF(AND(SIGN('🎯 Palpites'!J11-'🎯 Palpites'!K11)=SIGN('⚽ Jogos'!F10-'⚽ Jogos'!H10),('🎯 Palpites'!J11-'🎯 Palpites'!K11)=('⚽ Jogos'!F10-'⚽ Jogos'!H10)),2, IF(SIGN('🎯 Palpites'!J11-'🎯 Palpites'!K11)=SIGN('⚽ Jogos'!F10-'⚽ Jogos'!H10),1, 0)))) | H11: =IF(OR(NOT(ISNUMBER('⚽ Jogos'!F10)),NOT(ISNUMBER('⚽ Jogos'!H10)),NOT(ISNUMBER('🎯 Palpites'!L11)),NOT(ISNUMBER('🎯 Palpites'!M11))),"", IF(AND('🎯 Palpites'!L11='⚽ Jogos'!F10,'🎯 Palpites'!M11='⚽ Jogos'!H10),3, IF(AND(SIGN('🎯 Palpites'!L11-'🎯 Palpites'!M11)=SIGN('⚽ Jogos'!F10-'⚽ Jogos'!H10),('🎯 Palpites'!L11-'🎯 Palpites'!M11)=('⚽ Jogos'!F10-'⚽ Jogos'!H10)),2, IF(SIGN('🎯 Palpites'!L11-'🎯 Palpites'!M11)=SIGN('⚽ Jogos'!F10-'⚽ Jogos'!H10),1, 0)))) | I11: =IF(OR(NOT(ISNUMBER('⚽ Jogos'!F10)),NOT(ISNUMBER('⚽ Jogos'!H10)),NOT(ISNUMBER('🎯 Palpites'!N11)),NOT(ISNUMBER('🎯 Palpites'!O11))),"", IF(AND('🎯 Palpites'!N11='⚽ Jogos'!F10,'🎯 Palpites'!O11='⚽ Jogos'!H10),3, IF(AND(SIGN('🎯 Palpites'!N11-'🎯 Palpites'!O11)=SIGN('⚽ Jogos'!F10-'⚽ Jogos'!H10),('🎯 Palpites'!N11-'🎯 Palpites'!O11)=('⚽ Jogos'!F10-'⚽ Jogos'!H10)),2, IF(SIGN('🎯 Palpites'!N11-'🎯 Palpites'!O11)=SIGN('⚽ Jogos'!F10-'⚽ Jogos'!H10),1, 0)))) | J11: =IF(OR(NOT(ISNUMBER('⚽ Jogos'!F10)),NOT(ISNUMBER('⚽ Jogos'!H10)),NOT(ISNUMBER('🎯 Palpites'!P11)),NOT(ISNUMBER('🎯 Palpites'!Q11))),"", IF(AND('🎯 Palpites'!P11='⚽ Jogos'!F10,'🎯 Palpites'!Q11='⚽ Jogos'!H10),3, IF(AND(SIGN('🎯 Palpites'!P11-'🎯 Palpites'!Q11)=SIGN('⚽ Jogos'!F10-'⚽ Jogos'!H10),('🎯 Palpites'!P11-'🎯 Palpites'!Q11)=('⚽ Jogos'!F10-'⚽ Jogos'!H10)),2, IF(SIGN('🎯 Palpites'!P11-'🎯 Palpites'!Q11)=SIGN('⚽ Jogos'!F10-'⚽ Jogos'!H10),1, 0)))) | K11: =IF(OR(NOT(ISNUMBER('⚽ Jogos'!F10)),NOT(ISNUMBER('⚽ Jogos'!H10)),NOT(ISNUMBER('🎯 Palpites'!R11)),NOT(ISNUMBER('🎯 Palpites'!S11))),"", IF(AND('🎯 Palpites'!R11='⚽ Jogos'!F10,'🎯 Palpites'!S11='⚽ Jogos'!H10),3, IF(AND(SIGN('🎯 Palpites'!R11-'🎯 Palpites'!S11)=SIGN('⚽ Jogos'!F10-'⚽ Jogos'!H10),('🎯 Palpites'!R11-'🎯 Palpites'!S11)=('⚽ Jogos'!F10-'⚽ Jogos'!H10)),2, IF(SIGN('🎯 Palpites'!R11-'🎯 Palpites'!S11)=SIGN('⚽ Jogos'!F10-'⚽ Jogos'!H10),1, 0)))) | L11: =IF(OR(NOT(ISNUMBER('⚽ Jogos'!F10)),NOT(ISNUMBER('⚽ Jogos'!H10)),NOT(ISNUMBER('🎯 Palpites'!T11)),NOT(ISNUMBER('🎯 Palpites'!U11))),"", IF(AND('🎯 Palpites'!T11='⚽ Jogos'!F10,'🎯 Palpites'!U11='⚽ Jogos'!H10),3, IF(AND(SIGN('🎯 Palpites'!T11-'🎯 Palpites'!U11)=SIGN('⚽ Jogos'!F10-'⚽ Jogos'!H10),('🎯 Palpites'!T11-'🎯 Palpites'!U11)=('⚽ Jogos'!F10-'⚽ Jogos'!H10)),2, IF(SIGN('🎯 Palpites'!T11-'🎯 Palpites'!U11)=SIGN('⚽ Jogos'!F10-'⚽ Jogos'!H10),1, 0)))) | M11: =IF(OR(NOT(ISNUMBER('⚽ Jogos'!F10)),NOT(ISNUMBER('⚽ Jogos'!H10)),NOT(ISNUMBER('🎯 Palpites'!V11)),NOT(ISNUMBER('🎯 Palpites'!W11))),"", IF(AND('🎯 Palpites'!V11='⚽ Jogos'!F10,'🎯 Palpites'!W11='⚽ Jogos'!H10),3, IF(AND(SIGN('🎯 Palpites'!V11-'🎯 Palpites'!W11)=SIGN('⚽ Jogos'!F10-'⚽ Jogos'!H10),('🎯 Palpites'!V11-'🎯 Palpites'!W11)=('⚽ Jogos'!F10-'⚽ Jogos'!H10)),2, IF(SIGN('🎯 Palpites'!V11-'🎯 Palpites'!W11)=SIGN('⚽ Jogos'!F10-'⚽ Jogos'!H10),1, 0)))) | N11: =IF(OR(NOT(ISNUMBER('⚽ Jogos'!F10)),NOT(ISNUMBER('⚽ Jogos'!H10)),NOT(ISNUMBER('🎯 Palpites'!X11)),NOT(ISNUMBER('🎯 Palpites'!Y11))),"", IF(AND('🎯 Palpites'!X11='⚽ Jogos'!F10,'🎯 Palpites'!Y11='⚽ Jogos'!H10),3, IF(AND(SIGN('🎯 Palpites'!X11-'🎯 Palpites'!Y11)=SIGN('⚽ Jogos'!F10-'⚽ Jogos'!H10),('🎯 Palpites'!X11-'🎯 Palpites'!Y11)=('⚽ Jogos'!F10-'⚽ Jogos'!H10)),2, IF(SIGN('🎯 Palpites'!X11-'🎯 Palpites'!Y11)=SIGN('⚽ Jogos'!F10-'⚽ Jogos'!H10),1, 0)))) | O11: =IF(OR(NOT(ISNUMBER('⚽ Jogos'!F10)),NOT(ISNUMBER('⚽ Jogos'!H10)),NOT(ISNUMBER('🎯 Palpites (11-20)'!F11)),NOT(ISNUMBER('🎯 Palpites (11-20)'!G11))),"", IF(AND('🎯 Palpites (11-20)'!F11='⚽ Jogos'!F10,'🎯 Palpites (11-20)'!G11='⚽ Jogos'!H10),3, IF(AND(SIGN('🎯 Palpites (11-20)'!F11-'🎯 Palpites (11-20)'!G11)=SIGN('⚽ Jogos'!F10-'⚽ Jogos'!H10),('🎯 Palpites (11-20)'!F11-'🎯 Palpites (11-20)'!G11)=('⚽ Jogos'!F10-'⚽ Jogos'!H10)),2, IF(SIGN('🎯 Palpites (11-20)'!F11-'🎯 Palpites (11-20)'!G11)=SIGN('⚽ Jogos'!F10-'⚽ Jogos'!H10),1, 0)))) | P11: =IF(OR(NOT(ISNUMBER('⚽ Jogos'!F10)),NOT(ISNUMBER('⚽ Jogos'!H10)),NOT(ISNUMBER('🎯 Palpites (11-20)'!H11)),NOT(ISNUMBER('🎯 Palpites (11-20)'!I11))),"", IF(AND('🎯 Palpites (11-20)'!H11='⚽ Jogos'!F10,'🎯 Palpites (11-20)'!I11='⚽ Jogos'!H10),3, IF(AND(SIGN('🎯 Palpites (11-20)'!H11-'🎯 Palpites (11-20)'!I11)=SIGN('⚽ Jogos'!F10-'⚽ Jogos'!H10),('🎯 Palpites (11-20)'!H11-'🎯 Palpites (11-20)'!I11)=('⚽ Jogos'!F10-'⚽ Jogos'!H10)),2, IF(SIGN('🎯 Palpites (11-20)'!H11-'🎯 Palpites (11-20)'!I11)=SIGN('⚽ Jogos'!F10-'⚽ Jogos'!H10),1, 0)))) | Q11: =IF(OR(NOT(ISNUMBER('⚽ Jogos'!F10)),NOT(ISNUMBER('⚽ Jogos'!H10)),NOT(ISNUMBER('🎯 Palpites (11-20)'!J11)),NOT(ISNUMBER('🎯 Palpites (11-20)'!K11))),"", IF(AND('🎯 Palpites (11-20)'!J11='⚽ Jogos'!F10,'🎯 Palpites (11-20)'!K11='⚽ Jogos'!H10),3, IF(AND(SIGN('🎯 Palpites (11-20)'!J11-'🎯 Palpites (11-20)'!K11)=SIGN('⚽ Jogos'!F10-'⚽ Jogos'!H10),('🎯 Palpites (11-20)'!J11-'🎯 Palpites (11-20)'!K11)=('⚽ Jogos'!F10-'⚽ Jogos'!H10)),2, IF(SIGN('🎯 Palpites (11-20)'!J11-'🎯 Palpites (11-20)'!K11)=SIGN('⚽ Jogos'!F10-'⚽ Jogos'!H10),1, 0)))) | R11: =IF(OR(NOT(ISNUMBER('⚽ Jogos'!F10)),NOT(ISNUMBER('⚽ Jogos'!H10)),NOT(ISNUMBER('🎯 Palpites (11-20)'!L11)),NOT(ISNUMBER('🎯 Palpites (11-20)'!M11))),"", IF(AND('🎯 Palpites (11-20)'!L11='⚽ Jogos'!F10,'🎯 Palpites (11-20)'!M11='⚽ Jogos'!H10),3, IF(AND(SIGN('🎯 Palpites (11-20)'!L11-'🎯 Palpites (11-20)'!M11)=SIGN('⚽ Jogos'!F10-'⚽ Jogos'!H10),('🎯 Palpites (11-20)'!L11-'🎯 Palpites (11-20)'!M11)=('⚽ Jogos'!F10-'⚽ Jogos'!H10)),2, IF(SIGN('🎯 Palpites (11-20)'!L11-'🎯 Palpites (11-20)'!M11)=SIGN('⚽ Jogos'!F10-'⚽ Jogos'!H10),1, 0)))) | S11: =IF(OR(NOT(ISNUMBER('⚽ Jogos'!F10)),NOT(ISNUMBER('⚽ Jogos'!H10)),NOT(ISNUMBER('🎯 Palpites (11-20)'!N11)),NOT(ISNUMBER('🎯 Palpites (11-20)'!O11))),"", IF(AND('🎯 Palpites (11-20)'!N11='⚽ Jogos'!F10,'🎯 Palpites (11-20)'!O11='⚽ Jogos'!H10),3, IF(AND(SIGN('🎯 Palpites (11-20)'!N11-'🎯 Palpites (11-20)'!O11)=SIGN('⚽ Jogos'!F10-'⚽ Jogos'!H10),('🎯 Palpites (11-20)'!N11-'🎯 Palpites (11-20)'!O11)=('⚽ Jogos'!F10-'⚽ Jogos'!H10)),2, IF(SIGN('🎯 Palpites (11-20)'!N11-'🎯 Palpites (11-20)'!O11)=SIGN('⚽ Jogos'!F10-'⚽ Jogos'!H10),1, 0)))) | T11: =IF(OR(NOT(ISNUMBER('⚽ Jogos'!F10)),NOT(ISNUMBER('⚽ Jogos'!H10)),NOT(ISNUMBER('🎯 Palpites (11-20)'!P11)),NOT(ISNUMBER('🎯 Palpites (11-20)'!Q11))),"", IF(AND('🎯 Palpites (11-20)'!P11='⚽ Jogos'!F10,'🎯 Palpites (11-20)'!Q11='⚽ Jogos'!H10),3, IF(AND(SIGN('🎯 Palpites (11-20)'!P11-'🎯 Palpites (11-20)'!Q11)=SIGN('⚽ Jogos'!F10-'⚽ Jogos'!H10),('🎯 Palpites (11-20)'!P11-'🎯 Palpites (11-20)'!Q11)=('⚽ Jogos'!F10-'⚽ Jogos'!H10)),2, IF(SIGN('🎯 Palpites (11-20)'!P11-'🎯 Palpites (11-20)'!Q11)=SIGN('⚽ Jogos'!F10-'⚽ Jogos'!H10),1, 0)))) | U11: =IF(OR(NOT(ISNUMBER('⚽ Jogos'!F10)),NOT(ISNUMBER('⚽ Jogos'!H10)),NOT(ISNUMBER('🎯 Palpites (11-20)'!R11)),NOT(ISNUMBER('🎯 Palpites (11-20)'!S11))),"", IF(AND('🎯 Palpites (11-20)'!R11='⚽ Jogos'!F10,'🎯 Palpites (11-20)'!S11='⚽ Jogos'!H10),3, IF(AND(SIGN('🎯 Palpites (11-20)'!R11-'🎯 Palpites (11-20)'!S11)=SIGN('⚽ Jogos'!F10-'⚽ Jogos'!H10),('🎯 Palpites (11-20)'!R11-'🎯 Palpites (11-20)'!S11)=('⚽ Jogos'!F10-'⚽ Jogos'!H10)),2, IF(SIGN('🎯 Palpites (11-20)'!R11-'🎯 Palpites (11-20)'!S11)=SIGN('⚽ Jogos'!F10-'⚽ Jogos'!H10),1, 0)))) | V11: =IF(OR(NOT(ISNUMBER('⚽ Jogos'!F10)),NOT(ISNUMBER('⚽ Jogos'!H10)),NOT(ISNUMBER('🎯 Palpites (11-20)'!T11)),NOT(ISNUMBER('🎯 Palpites (11-20)'!U11))),"", IF(AND('🎯 Palpites (11-20)'!T11='⚽ Jogos'!F10,'🎯 Palpites (11-20)'!U11='⚽ Jogos'!H10),3, IF(AND(SIGN('🎯 Palpites (11-20)'!T11-'🎯 Palpites (11-20)'!U11)=SIGN('⚽ Jogos'!F10-'⚽ Jogos'!H10),('🎯 Palpites (11-20)'!T11-'🎯 Palpites (11-20)'!U11)=('⚽ Jogos'!F10-'⚽ Jogos'!H10)),2, IF(SIGN('🎯 Palpites (11-20)'!T11-'🎯 Palpites (11-20)'!U11)=SIGN('⚽ Jogos'!F10-'⚽ Jogos'!H10),1, 0)))) | W11: =IF(OR(NOT(ISNUMBER('⚽ Jogos'!F10)),NOT(ISNUMBER('⚽ Jogos'!H10)),NOT(ISNUMBER('🎯 Palpites (11-20)'!V11)),NOT(ISNUMBER('🎯 Palpites (11-20)'!W11))),"", IF(AND('🎯 Palpites (11-20)'!V11='⚽ Jogos'!F10,'🎯 Palpites (11-20)'!W11='⚽ Jogos'!H10),3, IF(AND(SIGN('🎯 Palpites (11-20)'!V11-'🎯 Palpites (11-20)'!W11)=SIGN('⚽ Jogos'!F10-'⚽ Jogos'!H10),('🎯 Palpites (11-20)'!V11-'🎯 Palpites (11-20)'!W11)=('⚽ Jogos'!F10-'⚽ Jogos'!H10)),2, IF(SIGN('🎯 Palpites (11-20)'!V11-'🎯 Palpites (11-20)'!W11)=SIGN('⚽ Jogos'!F10-'⚽ Jogos'!H10),1, 0)))) | X11: =IF(OR(NOT(ISNUMBER('⚽ Jogos'!F10)),NOT(ISNUMBER('⚽ Jogos'!H10)),NOT(ISNUMBER('🎯 Palpites (11-20)'!X11)),NOT(ISNUMBER('🎯 Palpites (11-20)'!Y11))),"", IF(AND('🎯 Palpites (11-20)'!X11='⚽ Jogos'!F10,'🎯 Palpites (11-20)'!Y11='⚽ Jogos'!H10),3, IF(AND(SIGN('🎯 Palpites (11-20)'!X11-'🎯 Palpites (11-20)'!Y11)=SIGN('⚽ Jogos'!F10-'⚽ Jogos'!H10),('🎯 Palpites (11-20)'!X11-'🎯 Palpites (11-20)'!Y11)=('⚽ Jogos'!F10-'⚽ Jogos'!H10)),2, IF(SIGN('🎯 Palpites (11-20)'!X11-'🎯 Palpites (11-20)'!Y11)=SIGN('⚽ Jogos'!F10-'⚽ Jogos'!H10),1, 0))))
